#VRML_SIM R2023b utf8

EXTERNPROTO "https://raw.githubusercontent.com/cyberbotics/webots/R2023b/projects/appearances/protos/OsbWood.proto"
EXTERNPROTO "https://raw.githubusercontent.com/cyberbotics/webots/R2023b/projects/objects/floors/protos/RectangleArena.proto"
EXTERNPROTO "https://raw.githubusercontent.com/cyberbotics/webots/R2023b/projects/objects/backgrounds/protos/TexturedBackground.proto"
EXTERNPROTO "https://raw.githubusercontent.com/cyberbotics/webots/R2023b/projects/objects/backgrounds/protos/TexturedBackgroundLight.proto"

WorldInfo {
  info [
    "In this example, the robot moves down a slope."
    "The altimeter is used to record the robots height."
  ]
  title "Altimeter"
  basicTimeStep 8
  contactProperties [
    ContactProperties {
      material2 "body"
      coulombFriction [
        0
      ]
      softCFM 0.1
    }
  ]
}
Viewpoint {
  orientation -0.2298671544258305 -0.9618378686452251 0.1484217159184663 5.961616242307235
  position -1.670155547737508 -0.024129187412778197 0.6251242985209675
}
TexturedBackground {
}
TexturedBackgroundLight {
}
RectangleArena {
}
PointLight {
  attenuation 0 0 1
  intensity 0.6
  location 0.6 0 0
}
DEF SLOPE Solid {
  translation 0 0 0.15
  rotation 0 1 0 -0.4
  children [
    Shape {
      appearance OsbWood {
        textureTransform TextureTransform {
          scale 0.5 2
        }
      }
      geometry DEF BOX0 Box {
        size 0.8 0.2 0.02
      }
    }
  ]
  name "green box"
  boundingObject USE BOX0
}
Robot {
  translation 0.15967865086714308 4.715944541721397e-05 0.2284733616343721
  rotation 0.24570212200682928 -0.032348216062959664 -0.9688054810739279 2.88783
  children [
    HingeJoint {
      jointParameters HingeJointParameters {
        axis 0 1 0
        anchor 0 0 0.025
      }
      device [
        DEF right_wheel_motor RotationalMotor {
          name "right wheel motor"
        }
        DEF right_wheel_sensor PositionSensor {
          name "left wheel sensor"
        }
      ]
      endPoint Solid {
        translation -0.0112875 -0.0492565 0.0262942
        rotation -0.17680001424208946 -0.047372903816114705 0.9831060791939118 1.58783
        children [
          DEF wheel Transform {
            rotation 0.5773502691896258 0.5773502691896258 -0.5773502691896258 -2.09
            children [
              Shape {
                appearance PBRAppearance {
                  baseColor 0.923598 0.116838 0.0758831
                  roughness 1
                  metalness 0
                }
                geometry Cylinder {
                  height 0.01
                  radius 0.025
                }
              }
            ]
            rotationStep 0.262
          }
        ]
        name "solid(1)"
      }
    }
    Transform {
    }
    HingeJoint {
      jointParameters HingeJointParameters {
        axis 0 1 0
        anchor 0 0 0.025
      }
      device [
        RotationalMotor {
          name "left wheel motor"
        }
        PositionSensor {
          name "left wheel sensor"
        }
      ]
      endPoint Solid {
        translation 0 0.045 0.025
        rotation -0.59973018211342 0.59973018211342 0.5297616608668544 -2.163185307179586
        children [
          DEF wheel Transform {
            rotation 0.5773502691896258 0.5773502691896258 -0.5773502691896258 -2.09
            children [
              Shape {
                appearance PBRAppearance {
                  baseColor 0.976532 0.359182 0.215976
                  roughness 1
                  metalness 0
                }
                geometry Cylinder {
                  height 0.01
                  radius 0.025
                }
              }
            ]
            translationStep 0.001
            rotationStep 0.262
          }
        ]
      }
    }
    Altimeter {
    }
    Pose {
      translation 0 0 0.0415
      children [
        Shape {
          appearance PBRAppearance {
            baseColor 0.0820075 0.364731 0.8
            roughness 1
            metalness 0
          }
          geometry DEF BODY Cylinder {
            height 0.08
            radius 0.045
          }
        }
      ]
    }
  ]
  name "MyBot"
  contactMaterial "body"
  boundingObject Pose {
    translation 0 0 0.0415
    rotation 0 0 1 -1.570796
    children [
      USE BODY
    ]
  }
  physics Physics {
    density -1
    mass 0.5
  }
  controller ""
}
